Workbook

Sheet Overview
A1: fsQCA 35-Firm Panel (2023-2025) - Read Me [v2: extended real research to all 35 firms]
A3: SCOPE | B3: 35 real semiconductor companies (USA, Taiwan, South Korea, Singapore) x 3 fiscal years (2023-2025) = 105 firm-year cases.
A5: WHAT CHANGED IN THIS VERSION | B5: The first version of this workbook had real research grounding for 13 of 35 firms. This version extends genuine, cited research to all 35 firms (22 additional companies researched: Micron, Analog Devices, Microchip, onsemi, Skyworks, Marvell, GlobalFoundries, UMC, MediaTek, Novatek, Realtek, ASE, Himax, Phison, Nanya, Samsung [additional], DB HiTek, LX Semicon, Hana Micron, AEM, UMS, Frencken, Venture). Two of the 35 (Novatek, Nanya, DB HiTek, UMS, Venture) still returned little to no company-specific real evidence despite a genuine search attempt -- their scores remain built from subsector/country/scale judgment (Simulated), and that is disclosed, not hidden.
A7: COMPOSITION AFTER THIS PASS | B7: Across all 735 construct-year cells: 57 Observed (7.8%), 114 Estimated (15.5%), 564 Simulated (76.7%). 29 of 35 companies now have at least one real, cited construct score (up from 13). This is still a minority-Observed dataset overall -- most of every company's profile is still Estimated/Simulated -- but the real-evidence base has grown meaningfully and covers every company at least once for the best-documented dimension (usually Sustainable Sourcing or AI Capability, the two most commonly disclosed).
A9: HOW THIS WAS BUILT - IMPORTANT, READ BEFORE USING
A10: 1. Real research | B10: Two research passes: the first covered the 13 largest/most-covered firms; the second covered the remaining 22. See the Data Sources tab for all 55 real citations found and exactly what each supports.
A11: 2. Construct-level, not indicator-level, grounding | B11: Given 35 firms x 3 years x 7 constructs, doing individually-cited evidence for every one of the ~5,000 underlying indicator cells was not feasible to do honestly. Scores are set at the CONSTRUCT level directly from what the real research found, or from documented, consistent subsector/country/company-scale judgment where it did not -- see Scoring Method tab for the exact rubric.
A12: 3. Data_Status meaning | B12: Observed = the company's 2024 score on that construct is grounded in a real, cited source (Data Sources tab). Estimated = derived from an Observed anchor via a documented, pre-specified year-on-year trend. Simulated = no direct citation found for that company-construct; scored from subsector/country/company-scale norms only.
A13: 4. Realistic complexity preserved | B13: Per-company idiosyncratic variation and small noise sit on top of the general trend (see Scoring Method), and specific real events were applied where documented (TSMC's Arizona expansion raising SUPDIV in 2025; Wolfspeed's June 2025 Chapter 11 filing lowering SCR/SUPCOLL that year; LX Semicon's UN Global Compact membership and first sustainability report dating from late 2023, so its SUSSRC/AIGOV anchor is lower in 2023 than in 2024). Nothing was adjusted after the fact to change the truth table -- the noise seed and trend parameters were fixed before the truth table was computed, both times.
A14: 5. Do not cite as a real empirical dataset without this disclosure | B14: Even after this expanded pass, most Data_Status values are Estimated or Simulated. If this feeds into the paper, the composition must be disclosed the same way as the earlier synthetic datasets in this project.
A16: TABS IN THIS WORKBOOK
A17: Company List | B17: Output 1 - all 35 firms with ticker, country, subsector, HQ
A18: Raw Data (0-4 Scores) | B18: Output 2 - 105-row raw construct dataset (0-4 scale) with Data_Status per construct
A19: Data Sources | B19: Output 4 (partial by design - see note 2) - all 55 real citations, with the exact company/construct/finding each supports
A20: Scoring Method | B20: Output 5 - exact rubric and trend/noise/event methodology
A21: Calibration Anchors | B21: Output 6 - 5th/50th/95th percentile anchors per variable
A22: Fuzzy Scores (Source) | B22: Output 7 - 105-row fuzzy membership dataset (fz_ columns, 6 decimal places)
A23: Calibration Check | B23: Output 8 - min/max/median/counts per variable
A24: Truth Table - Empirical | B24: empirically observed configurations, sorted by frequency
A25: Truth Table - Complete 64 | B25: all 64 logical configurations, remainders included

Sheet Revision History
A1: REVISION NOTES (v2) - what was added and why
A3: Original sheets | B3: All ten original sheets are untouched. Everything below is new and formula-driven from Raw Data (0-4 Scores) / Fuzzy Scores (Source).
A4: Corrected retention rule | B4: Original Retained_conventional = frequency >= 2 and raw consistency >= 0.80, with no PRI condition. That kept 5 rows with PRI 0.17-0.35, below the guideline minimum of 0.50 (Pappas & Woodside 2021). The corrected rule adds PRI >= 0.50 and requires at least 2 distinct firms behind a row.
A5: Variant 1: percentile anchors | B5: Delivered calibration (5th/50th/95th percentile). Fuzzy values are linked to the Fuzzy Scores (Source) sheet, so frequencies and raw consistencies reproduce the original truth table.
A6: Variant 2: rubric anchors | B6: Anchors 1 / 2 / 3 on the 0-4 rubric (very limited / moderate / substantial), editable on Analysis Settings. Added because median crossovers force ~50% membership in every set and put the AIGOV crossover (1.14) below "moderate". Report both variants as a robustness check.
A7: Known small discrepancy | B7: PRI in 5 percentile-variant rows differs from the original Truth Table - Complete 64 sheet by up to 0.017 (largest: config 0,0,0,0,0,1: 0.417 here vs 0.434 originally). The cause was not identified. No retention decision changes.
A8: Not changed: Read Me | B8: The original Read Me says "Two of the 35 (Novatek, Nanya, DB HiTek, UMS, Venture)". Six firms have no Observed cell: DB HiTek, Nanya, Novatek, Realtek, UMS, Venture. Correct the text before circulating.
A9: Data caveat | B9: 76.7% of construct-year cells are Simulated; SCR itself is 90 Simulated, 10 Estimated, 5 Observed of 105. Solutions from either variant describe the scoring process, not real resilience, until the outcome is measured independently.
A10: Not yet done | B10: Necessity here covers SCR only. Still to run in fsQCA 4.0 / R QCA: Boolean minimization (complex, parsimonious, intermediate), the ~SCR truth table, and panel robustness (per-year, between/within, leave-one-country-out).
A11: Sheet guide | B11: Analysis Settings -> Fuzzy Pctl/Rubric v2 -> Mem Pctl/Rubric v2 (case x configuration) -> TT Pctl/Rubric v2 (truth tables, OUT column ready for fsQCA) -> Threshold Sensitivity, Necessity Analysis.
A13: Live summary (default thresholds)
A14: Percentile: rows retained, original rule | B14: 14
A15: Percentile: rows retained, corrected rule | B15: 7
A16: Rubric: rows retained, corrected rule | B16: 11
A17: Calibration anchors check (percentile vs Calibration Anchors) | B17: =IF(COUNTIF('Analysis Settings'!$H$15:$H$21,"OK")=7,"OK","CHECK") -> OK
A20: v3 additions - sufficiency and Boolean minimization
A21: TT sheets, columns S-W | B21: Truth-table statistics and OUT column for the negated outcome (~SCR), same corrected retention rule.
A22: Sufficiency Analysis | B22: Single-condition sufficiency (consistency, PRI, coverage) for each condition and its negation, both outcomes, both calibrations. Live formulas.
A23: Configurational Solutions | B23: Complex, parsimonious and intermediate solutions for SCR and ~SCR under both calibrations, with solution and term consistency, PRI, raw and unique coverage (live formulas) and core/peripheral labels.
A24: Solution Term Detail | B24: Helper sheet: each term specification (static output of Boolean minimization) and its case-level memberships (formulas).
A25: Method note | B25: Minimization was run offline with a Python implementation of Quine-McCluskey and Petrick minimal covers. Rows with < 2 firm-years or < 2 firms are remainders. Intermediate solution uses easy counterfactuals only, directional expectation = all six conditions help SCR when present. Cross-check in fsQCA 4.0 before reporting.
A27: Project files (split)
A28: File 1 - Data & Calibration | B28: Raw scores, sources, scoring method, calibration, descriptive statistics, fuzzy scores (live formulas)
A29: File 2 - Truth Tables | B29: Case memberships, truth tables, threshold sensitivity (values only)
A30: File 3 - Results | B30: Necessity, sufficiency, configurational solutions (values only)

Sheet Company List
A1: Company | B1: Ticker | C1: Country | D1: Subsector | E1: HQ
A2: Intel Corporation | B2: INTC | C2: USA | D2: IDM | E2: Santa Clara, CA, USA
A3: NVIDIA Corporation | B3: NVDA | C3: USA | D3: Fabless | E3: Santa Clara, CA, USA
A4: Advanced Micro Devices | B4: AMD | C4: USA | D4: Fabless | E4: Santa Clara, CA, USA
A5: Qualcomm Incorporated | B5: QCOM | C5: USA | D5: Fabless | E5: San Diego, CA, USA
A6: Broadcom Inc. | B6: AVGO | C6: USA | D6: Fabless/IDM | E6: Palo Alto, CA, USA
A7: Texas Instruments | B7: TXN | C7: USA | D7: IDM (analog) | E7: Dallas, TX, USA
A8: Micron Technology | B8: MU | C8: USA | D8: IDM (memory) | E8: Boise, ID, USA
A9: Applied Materials | B9: AMAT | C9: USA | D9: Equipment | E9: Santa Clara, CA, USA
A10: Lam Research | B10: LRCX | C10: USA | D10: Equipment | E10: Fremont, CA, USA
A11: KLA Corporation | B11: KLAC | C11: USA | D11: Equipment | E11: Milpitas, CA, USA
A12: Analog Devices | B12: ADI | C12: USA | D12: IDM (analog) | E12: Wilmington, MA, USA
... A36: Venture Corporation | B36: V03.SI | C36: Singapore | D36: Electronics manufacturing services | E36: Singapore

Sheet Raw Data (0-4 Scores)
A1: Company | B1: Ticker | C1: Country | D1: Subsector | E1: Year | F1: Revenue_USD_Million | G1: RD_USD_Million | H1: RD_Intensity | I1: Fin_Status | J1: AICAP | K1: AIGOV | L1: SUSSRC | M1: DIGVIS | N1: SUPCOLL | O1: SUPDIV | P1: SCR
A2: AEM Holdings | B2: AEM.SI | C2: Singapore | D2: Equipment (test handlers) | E2: 2023 | F2: 279 | G2: 14 | H2: 0.0502 | I2: Estimated | J2: 2.28 | K2: 0.4 | L2: 1.73 | M2: 1.5 | N2: 0.73 | O2: 1.24 | P2: 1.63
A3: AEM Holdings | B3: AEM.SI | C3: Singapore | D3: Equipment (test handlers) | E3: 2024 | F3: 300 | G3: 15 | H3: 0.05 | I3: Estimated | J3: 3.04 | K3: 0.88 | L3: 1.8 | M3: 1.84 | N3: 0.92 | O3: 0.89 | P3: 1.86
A4: AEM Holdings | B4: AEM.SI | C4: Singapore | D4: Equipment (test handlers) | E4: 2025 | F4: 321 | G4: 16.1 | H4: 0.0502 | I4: Estimated | J4: 3.11 | K4: 1.08 | L4: 2.05 | M4: 2.45 | N4: 1.22 | O4: 1.6 | P4: 2.15
A5: ASE Technology Holding | B5: ASX/3711.TW | C5: Taiwan | D5: OSAT | E5: 2023 | F5: 17856 | G5: 325.5 | H5: 0.0182 | I5: Estimated | J5: 1.53 | K5: 0.59 | L5: 2.78 | M5: 1.64 | N5: 3.57 | O5: 2.14 | P5: 3
A6: ASE Technology Holding | B6: ASX/3711.TW | C6: Taiwan | D6: OSAT | E6: 2024 | F6: 19200 | G6: 350 | H6: 0.0182 | I6: Estimated | J6: 2.05 | K6: 1.09 | L6: 3.14 | M6: 2.02 | N6: 4 | O6: 1.85 | P6: 2.92
A7: ASE Technology Holding | B7: ASX/3711.TW | C7: Taiwan | D7: OSAT | E7: 2025 | F7: 20544 | G7: 374.5 | H7: 0.0182 | I7: Estimated | J7: 1.92 | K7: 1.35 | L7: 3.09 | M7: 2.04 | N7: 4 | O7: 2.3 | P7: 3.22
A8: Advanced Micro Devices | B8: AMD | C8: USA | D8: Fabless | E8: 2023 | F8: 23980.1 | G8: 6047.8 | H8: 0.2522 | I8: Estimated | J8: 3.38 | K8: 2.76 | L8: 2.93 | M8: 1.88 | N8: 2.61 | O8: 1.85 | P8: 3.01
A9: Advanced Micro Devices | B9: AMD | C9: USA | D9: Fabless | E9: 2024 | F9: 25785 | G9: 6503 | H9: 0.2522 | I9: Observed | J9: 4 | K9: 2.74 | L9: 3.13 | M9: 2.04 | N9: 3.1 | O9: 1.9 | P9: 3.24
A10: Advanced Micro Devices | B10: AMD | C10: USA | D10: Fabless | E10: 2025 | F10: 27590 | G10: 6958.2 | H10: 0.2522 | I10: Estimated | J10: 4 | K10: 3.2 | L10: 3.34 | M10: 2.5 | N10: 3.1 | O10: 2.35 | P10: 3.43
A11: Analog Devices | B11: ADI | C11: USA | D11: IDM (analog) | E11: 2023 | F11: 8767.1 | G11: 1482.4 | H11: 0.1691 | I11: Estimated | J11: 0.57 | K11: 0.66 | L11: 2.84 | M11: 1.62 | N11: 1.67 | O11: 1.93 | P11: 2.77
A12: Analog Devices | B12: ADI | C12: USA | D12: IDM (analog) | E12: 2024 | F12: 9427 | G12: 1594 | H12: 0.1691 | I12: Observed | J12: 1.06 | K12: 0.89 | L12: 2.87 | M12: 1.98 | N12: 2.08 | O12: 1.96 | P12: 2.88
A13: Analog Devices | B13: ADI | C13: USA | D13: IDM (analog) | E13: 2025 | F13: 10086.9 | G13: 1705.6 | H13: 0.1691 | I13: Estimated | J13: 1.34 | K13: 1.31 | L13: 3.03 | M13: 2.58 | N13: 2.31 | O13: 2.43 | P13: 3.22
... A106: onsemi | B106: ON | C106: USA | D106: IDM | E106: 2025 | F106: 6822.3 | G106: 720.1 | H106: 0.1056 | I106: Estimated | J106: 2.32 | K106: 1.63 | L106: 4 | M106: 2 | N106: 2.98 | O106: 1.81 | P106: 2.15

Sheet Data Sources
A1: Company | B1: Construct | C1: Year_of_Evidence | D1: Evidence | E1: Source_Document | F1: URL
A2: Intel Corporation | B2: AIGOV | C2: 2024 | D2: Responsible AI Principles updated and made public; part of MLCommons, The AI Alliance, NIST | E2: Intel 2023-24 Corporate Responsibility Report | F2: https://csrreportbuilder.intel.com/pdfbuilder/pdfs/CSR-2023-24-Full-Report.pdf
A3: Intel Corporation | B3: SUSSRC | C3: 2023 | D3: $27M in fees returned to suppliers' workers since 2014; 25% of high-risk suppliers verified via human rights audits | E3: Intel 2023-24 CR Report / DEF 14A FY2024 | F3: https://www.sec.gov/Archives/edgar/data/50863/000005086324000057/proxycourtesypdf2024.pdf
A4: Intel Corporation | B4: SUPDIV | C4: 2023 | D4: Moonshot goal: 50% of global semiconductors produced in US/Europe by end of decade | E4: Intel 2023-24 CR Report Executive Summary | F4: https://csrreportbuilder.intel.com/pdfbuilder/pdfs/CSR-2023-24-Executive-Summary.pdf
A5: NVIDIA Corporation | B5: AICAP | C5: 2024 | D5: Core business built on accelerated computing / generative AI; Earth-2 digital twin platform for climate research | E5: NVIDIA FY2024 Sustainability Report | F5: https://images.nvidia.com/aem-dam/Solutions/documents/FY2024-NVIDIA-Corporate-Sustainability-Report.pdf
A6: NVIDIA Corporation | B6: SUSSRC | C6: 2024 | D6: 93% of strategic suppliers audited over the past two years; RBA Code of Conduct adopted | E6: NVIDIA FY2024 Sustainability Report summary | F6: https://www.sustainabilityreports.com/nvidia/2024/sustainability-report
A7: NVIDIA Corporation | B7: SUPDIV | C7: 2023 | D7: CEO Jensen Huang: supply chain 'designed for maximum diversity', open to TSMC/Samsung/Intel | E7: Taipei Times, May 2023 | F7: https://news.ltn.com.tw/news/focus/breakingnews/4318393
A8: Advanced Micro Devices | B8: AICAP | C8: 2024 | D8: AMD Instinct MI350 / EPYC delivering 38.5x node-level AI training energy efficiency gain 2020-2025 | E8: AMD 2024-25 Corporate Responsibility Report blog | F8: https://www.amd.com/en/blogs/2025/amd-launches-2024-25-corporate-responsibility-report.html
A9: Advanced Micro Devices | B9: AIGOV | C9: 2023 | D9: Responsible AI Council established 2023; engaged with Responsible AI Institute evaluation | E9: AMD 2023-24 CR Report (Lisa Su letter) | F9: https://csrwire.com/press-release/amd-2023-24-corporate-responsibility-report-message-dr-lisa-su-amd-chair-and/
A10: Advanced Micro Devices | B10: SUSSRC | C10: 2023 | D10: 84% of AMD manufacturing suppliers RBA-audited; 100% of 3TG smelters conflict-free (RMAP) | E10: AMD 2023-24 CR Report coverage | F10: https://www.techporn.ph/amd-releases-2023-24-corporate-responsibility-report/
A11: Qualcomm Incorporated | B11: AIGOV | C11: 2024 | D11: Responsible AI factsheet published; active in ISO/ITU/CEN-CENELEC/ETSI standards bodies | E11: Qualcomm Responsible AI page | F11: https://www.qualcomm.com/artificial-intelligence/responsible-ai
A12: Qualcomm Incorporated | B12: SUSSRC | C12: 2023 | D12: Full RBA member; Supplier Code of Conduct = RBA Code of Conduct; primary foundries/assembly suppliers assessed | E12: Qualcomm 2023 CR Report - Supply Chain Management | F12: https://csrwire.com/press-release/qualcomms-2023-corporate-responsibility-report-supply-chain-management/
A13: Broadcom Inc. | B13: SUSSRC | C13: 2023 | D13: 100% response rate on 3TG conflict-minerals supplier survey; 222/228 SORs RMAP-conformant | E13: Broadcom Form SD FY2024 (SEC) | F13: https://www.sec.gov/Archives/edgar/data/1730168/000173016824000073/exhibit101conflict-mineral.htm
... A56: Frencken Group | B56: SCR | C56: 2024 | D56: 2024 Annual Report titled 'Resilience and sustainable growth' | E56: Frencken Group 2024 Annual Report (SGX) | F56: https://links.sgx.com/1.0.0/corporate-announcements/AK1792UAJ4C47AN6/839402_Frencken%20AR2024.pdf

Sheet Scoring Method
A1: SCORE CONSTRUCTION METHODOLOGY
A2: Rubric (0-4, applied consistently across all companies/years/constructs)
A3: 0 | B3: No evidence / negligible - no public disclosure or program found, and no reasonable subsector basis to assume one
A4: 1 | B4: Very limited - mentioned briefly, nascent/minimal program, or typical of a small/under-disclosing peer in that subsector
A5: 2 | B5: Moderate - a documented program exists with moderate scope/maturity; the subsector/company-scale norm for a mid-sized player
A6: 3 | B6: Substantial - well-documented, comprehensive program, at or above industry standard
A7: 4 | B7: Extensive - industry-leading, comprehensive, quantified, multi-year track record (only assigned where research found this explicitly)
A9: 2024 anchor | B9: Each company's 2024 score per construct was set directly from the research pass (Observed, for the 29 companies with at least one real citation - see Data Sources) or from informed subsector/country/company-scale judgment (Simulated).
A10: 2023 / 2025 values | B10: Anchor +/- (years_from_2024 x annual_drift) +/- (idiosyncratic per-company offset x |years_from_2024|) + small random noise, clipped to [0,4].
A11: Annual drift by construct | B11: AICAP/AIGOV/DIGVIS: +0.35/yr (real, industry-wide AI acceleration 2023-2025). SUSSRC: +0.15/yr (slower ESG-reporting maturation). SUPCOLL/SUPDIV/SCR: +0.20/yr (gradual post-2022-shortage resilience investment).
A12: Idiosyncratic offset | B12: A fixed per-company-per-construct random draw (Normal, mean 0, sd 0.18), seeded deterministically from the company name, applied BEFORE any truth table was computed - not tuned to any result.
A13: Noise | B13: Independent per company-construct-year draw (Normal, mean 0, sd 0.12), same seeding discipline as above.
A14: Documented event overrides (real, not tuned)
A15: Wolfspeed, 2025 | B15: SCR -1, SUPCOLL -1 (Chapter 11 bankruptcy filed June 30, 2025)
A16: Taiwan Semiconductor Mfg. Co., 2025 | B16: SUPDIV +1 (Arizona fab ramp / US$65bn expansion)
A17: LX Semicon, 2023 | B17: SUSSRC -1, AIGOV -1 (its first sustainability report and UN Global Compact membership date to late 2023/2024, so the 2023 anchor sits below the 2024 one it was built from)
A19: What this is NOT | B19: This is not a claim that any specific 2023 or 2025 raw score is itself independently observed. Only the 2024 anchor for the flagged company-constructs is grounded in a real citation; the temporal path around it is a documented, pre-specified model, consistent with the Estimated/Simulated tiers your brief defines.

Sheet Calibration Anchors
A1: Variable | B1: 5th_percentile (e) | C1: 50th_percentile (c) | D1: 95th_percentile (i)
A2: AICAP | B2: 0.5 | C2: 2.03 | D2: 4
A3: AIGOV | B3: 0.47 | C3: 1.14 | D3: 3.144
A4: SUSSRC | B4: 0.962 | C4: 2.85 | D4: 4
A5: DIGVIS | B5: 0.694 | C5: 1.9 | D5: 3.47
A6: SUPCOLL | B6: 0.942 | C6: 2.36 | D6: 4
A7: SUPDIV | B7: 0.794 | C7: 1.93 | D7: 4
A8: SCR | B8: 0.96 | C8: 2.43 | D8: 3.756

Sheet Fuzzy Scores (Source)
A1: Company | B1: Ticker | C1: Year | D1: fz_AICAP | E1: fz_AIGOV | F1: fz_SUSSRC | G1: fz_DIGVIS | H1: fz_SUPCOLL | I1: fz_SUPDIV | J1: fz_SCR
A2: AEM Holdings | B2: AEM.SI | C2: 2023 | D2: 0.592343 | E2: 0.037253 | F2: 0.148464 | G2: 0.273568 | H2: 0.032779 | I2: 0.143265 | J2: 0.167644
A3: AEM Holdings | B3: AEM.SI | C3: 2024 | D3: 0.819 | E3: 0.24184 | F3: 0.162801 | G3: 0.463443 | H3: 0.047874 | I3: 0.063233 | J3: 0.242004
A4: AEM Holdings | B4: AEM.SI | C4: 2025 | D4: 0.833995 | E4: 0.434459 | F4: 0.223108 | G4: 0.737205 | H4: 0.08571 | I4: 0.298314 | J4: 0.363352
A5: ASE Technology Holding | B5: ASX/3711.TW | C5: 2023 | D5: 0.276431 | E5: 0.08188 | F5: 0.472735 | G5: 0.346426 | H5: 0.897745 | I5: 0.574127 | J5: 0.780007
A6: ASE Technology Holding | B6: ASX/3711.TW | C6: 2024 | D6: 0.507473 | E6: 0.445286 | F6: 0.677545 | G6: 0.556027 | H6: 0.95 | I6: 0.448346 | J6: 0.748017
A7: ASE Technology Holding | B7: ASX/3711.TW | C7: 2025 | D7: 0.447274 | E7: 0.576531 | F7: 0.648965 | G7: 0.565266 | H7: 0.95 | I7: 0.62862 | J7: 0.852485
A8: Advanced Micro Devices | B8: AMD | C8: 2023 | D8: 0.882649 | E8: 0.915308 | F8: 0.551029 | G8: 0.487795 | H8: 0.610365 | I8: 0.448346 | J8: 0.783794
A9: Advanced Micro Devices | B9: AMD | C9: 2024 | D9: 0.95 | E9: 0.913002 | F9: 0.671926 | G9: 0.565266 | H9: 0.790607 | I9: 0.48057 | J9: 0.857983
A10: Advanced Micro Devices | B10: AMD | C10: 2025 | D10: 0.95 | E10: 0.953767 | F10: 0.778093 | G10: 0.754964 | H10: 0.790607 | I10: 0.645066 | J10: 0.902079
A11: Analog Devices | B11: ADI | C11: 2023 | D11: 0.056801 | E11: 0.108182 | F11: 0.496101 | G11: 0.335454 | H11: 0.192668 | I11: 0.501 | J11: 0.680264
A12: Analog Devices | B12: ADI | C12: 2024 | D12: 0.13392 | E12: 0.249989 | F12: 0.512799 | G12: 0.537439 | H12: 0.358608 | I12: 0.510667 | J12: 0.73091
A13: Analog Devices | B13: ADI | C13: 2025 | D13: 0.20951 | E13: 0.562122 | F13: 0.61322 | G13: 0.781648 | H13: 0.474067 | I13: 0.67067 | J13: 0.852485
... A106: onsemi | B106: ON | C106: 2025 | D106: 0.606696 | E106: 0.672595 | F106: 0.95 | G106: 0.546749 | H106: 0.752714 | I106: 0.422863 | J106: 0.363352

Sheet Calibration Check
A1: Variable | B1: Min_fz | C1: Max_fz | D1: Median_fz | E1: N_below_0.5 | F1: N_above_0.5 | G1: N_equal_0.5 | H1: N_unique
A2: AICAP | B2: 0.0247 | C2: 0.95 | D2: 0.501 | E2: 52 | F2: 53 | G2: 0 | H2: 86
A3: AIGOV | B3: 0.0133 | C3: 0.9756 | D3: 0.501 | E3: 50 | F3: 55 | G3: 0 | H3: 83
A4: SUSSRC | B4: 0.0265 | C4: 0.95 | D4: 0.501 | E4: 50 | F4: 55 | G4: 0 | H4: 80
A5: DIGVIS | B5: 0.0275 | C5: 0.9809 | D5: 0.501 | E5: 52 | F5: 53 | G5: 0 | H5: 92
A6: SUPCOLL | B6: 0.0279 | C6: 0.95 | D6: 0.501 | E6: 52 | F6: 53 | G6: 0 | H6: 78
A7: SUPDIV | B7: 0.0234 | C7: 0.95 | D7: 0.501 | E7: 52 | F7: 53 | G7: 0 | H7: 86
A8: SCR | B8: 0.0226 | C8: 0.9703 | D8: 0.501 | E8: 52 | F8: 53 | G8: 0 | H8: 84

Sheet Descriptives & Correlations
A1: DESCRIPTIVE STATISTICS AND CORRELATION MATRIX – Raw Construct Scores (0–4 scale, 105 firm-year cases)
A2: All values are live formulas referencing the Raw Data (0-4 Scores) tab (AVERAGE, STDEV, MIN, MAX, COUNT, CORREL) and recalculate automatically if the raw scores change. Pearson correlation coefficients (CORREL) range from −1 to +1; SCR is the outcome, included here for reference alongside the six conditions.
A4: Descriptive Statistics
A5: Variable | B5: N | C5: Mean | D5: Std. Dev. | E5: Min | F5: Max
A6: AICAP | B6: =COUNT('Raw Data (0-4 Scores)'!J2:J106) -> 105 | C6: =AVERAGE('Raw Data (0-4 Scores)'!J2:J106) -> 2.1242857 | D6: =STDEV('Raw Data (0-4 Scores)'!J2:J106) -> 1.1395941 | E6: =MIN('Raw Data (0-4 Scores)'!J2:J106) -> 0.12 | F6: =MAX('Raw Data (0-4 Scores)'!J2:J106) -> 4
A7: AIGOV | B7: =COUNT('Raw Data (0-4 Scores)'!K2:K106) -> 105 | C7: =AVERAGE('Raw Data (0-4 Scores)'!K2:K106) -> 1.440381 | D7: =STDEV('Raw Data (0-4 Scores)'!K2:K106) -> 0.84826625 | E7: =MIN('Raw Data (0-4 Scores)'!K2:K106) -> 0.16 | F7: =MAX('Raw Data (0-4 Scores)'!K2:K106) -> 3.65
A8: SUSSRC | B8: =COUNT('Raw Data (0-4 Scores)'!L2:L106) -> 105 | C8: =AVERAGE('Raw Data (0-4 Scores)'!L2:L106) -> 2.6140952 | D8: =STDEV('Raw Data (0-4 Scores)'!L2:L106) -> 0.8632148 | E8: =MIN('Raw Data (0-4 Scores)'!L2:L106) -> 0.54 | F8: =MAX('Raw Data (0-4 Scores)'!L2:L106) -> 4
A9: DIGVIS | B9: =COUNT('Raw Data (0-4 Scores)'!M2:M106) -> 105 | C9: =AVERAGE('Raw Data (0-4 Scores)'!M2:M106) -> 1.9675238 | D9: =STDEV('Raw Data (0-4 Scores)'!M2:M106) -> 0.84331623 | E9: =MIN('Raw Data (0-4 Scores)'!M2:M106) -> 0.44 | F9: =MAX('Raw Data (0-4 Scores)'!M2:M106) -> 4
A10: SUPCOLL | B10: =COUNT('Raw Data (0-4 Scores)'!N2:N106) -> 105 | C10: =AVERAGE('Raw Data (0-4 Scores)'!N2:N106) -> 2.3773333 | D10: =STDEV('Raw Data (0-4 Scores)'!N2:N106) -> 0.92667444 | E10: =MIN('Raw Data (0-4 Scores)'!N2:N106) -> 0.65 | F10: =MAX('Raw Data (0-4 Scores)'!N2:N106) -> 4
A11: SUPDIV | B11: =COUNT('Raw Data (0-4 Scores)'!O2:O106) -> 105 | C11: =AVERAGE('Raw Data (0-4 Scores)'!O2:O106) -> 2.0699048 | D11: =STDEV('Raw Data (0-4 Scores)'!O2:O106) -> 1.0030641 | E11: =MIN('Raw Data (0-4 Scores)'!O2:O106) -> 0.49 | F11: =MAX('Raw Data (0-4 Scores)'!O2:O106) -> 4
A12: SCR | B12: =COUNT('Raw Data (0-4 Scores)'!P2:P106) -> 105 | C12: =AVERAGE('Raw Data (0-4 Scores)'!P2:P106) -> 2.3794286 | D12: =STDEV('Raw Data (0-4 Scores)'!P2:P106) -> 0.86073071 | E12: =MIN('Raw Data (0-4 Scores)'!P2:P106) -> 0.55 | F12: =MAX('Raw Data (0-4 Scores)'!P2:P106) -> 4
A14: Pearson Correlation Matrix
B15: AICAP | C15: AIGOV | D15: SUSSRC | E15: DIGVIS | F15: SUPCOLL | G15: SUPDIV | H15: SCR
A16: AICAP | B16: =CORREL('Raw Data (0-4 Scores)'!J2:J106,'Raw Data (0-4 Scores)'!J2:J106) -> 1 | C16: =CORREL('Raw Data (0-4 Scores)'!J2:J106,'Raw Data (0-4 Scores)'!K2:K106) -> 0.64130562 | D16: =CORREL('Raw Data (0-4 Scores)'!J2:J106,'Raw Data (0-4 Scores)'!L2:L106) -> 0.31269389 | E16: =CORREL('Raw Data (0-4 Scores)'!J2:J106,'Raw Data (0-4 Scores)'!M2:M106) -> 0.63777795 | F16: =CORREL('Raw Data (0-4 Scores)'!J2:J106,'Raw Data (0-4 Scores)'!N2:N106) -> 0.41031836 | G16: =CORREL('Raw Data (0-4 Scores)'!J2:J106,'Raw Data (0-4 Scores)'!O2:O106) -> 0.27637101 | H16: =CORREL('Raw Data (0-4 Scores)'!J2:J106,'Raw Data (0-4 Scores)'!P2:P106) -> 0.4526654
A17: AIGOV | B17: =CORREL('Raw Data (0-4 Scores)'!K2:K106,'Raw Data (0-4 Scores)'!J2:J106) -> 0.64130562 | C17: =CORREL('Raw Data (0-4 Scores)'!K2:K106,'Raw Data (0-4 Scores)'!K2:K106) -> 1 | D17: =CORREL('Raw Data (0-4 Scores)'!K2:K106,'Raw Data (0-4 Scores)'!L2:L106) -> 0.39638252 | E17: =CORREL('Raw Data (0-4 Scores)'!K2:K106,'Raw Data (0-4 Scores)'!M2:M106) -> 0.62220169 | F17: =CORREL('Raw Data (0-4 Scores)'!K2:K106,'Raw Data (0-4 Scores)'!N2:N106) -> 0.38036517 | G17: =CORREL('Raw Data (0-4 Scores)'!K2:K106,'Raw Data (0-4 Scores)'!O2:O106) -> 0.48197541 | H17: =CORREL('Raw Data (0-4 Scores)'!K2:K106,'Raw Data (0-4 Scores)'!P2:P106) -> 0.44642969
A18: SUSSRC | B18: =CORREL('Raw Data (0-4 Scores)'!L2:L106,'Raw Data (0-4 Scores)'!J2:J106) -> 0.31269389 | C18: =CORREL('Raw Data (0-4 Scores)'!L2:L106,'Raw Data (0-4 Scores)'!K2:K106) -> 0.39638252 | D18: =CORREL('Raw Data (0-4 Scores)'!L2:L106,'Raw Data (0-4 Scores)'!L2:L106) -> 1 | E18: =CORREL('Raw Data (0-4 Scores)'!L2:L106,'Raw Data (0-4 Scores)'!M2:M106) -> 0.53143103 | F18: =CORREL('Raw Data (0-4 Scores)'!L2:L106,'Raw Data (0-4 Scores)'!N2:N106) -> 0.53720152 | G18: =CORREL('Raw Data (0-4 Scores)'!L2:L106,'Raw Data (0-4 Scores)'!O2:O106) -> 0.28096397 | H18: =CORREL('Raw Data (0-4 Scores)'!L2:L106,'Raw Data (0-4 Scores)'!P2:P106) -> 0.39243361
A19: DIGVIS | B19: =CORREL('Raw Data (0-4 Scores)'!M2:M106,'Raw Data (0-4 Scores)'!J2:J106) -> 0.63777795 | C19: =CORREL('Raw Data (0-4 Scores)'!M2:M106,'Raw Data (0-4 Scores)'!K2:K106) -> 0.62220169 | D19: =CORREL('Raw Data (0-4 Scores)'!M2:M106,'Raw Data (0-4 Scores)'!L2:L106) -> 0.53143103 | E19: =CORREL('Raw Data (0-4 Scores)'!M2:M106,'Raw Data (0-4 Scores)'!M2:M106) -> 1 | F19: =CORREL('Raw Data (0-4 Scores)'!M2:M106,'Raw Data (0-4 Scores)'!N2:N106) -> 0.6184411 | G19: =CORREL('Raw Data (0-4 Scores)'!M2:M106,'Raw Data (0-4 Scores)'!O2:O106) -> 0.60272699 | H19: =CORREL('Raw Data (0-4 Scores)'!M2:M106,'Raw Data (0-4 Scores)'!P2:P106) -> 0.66462919
A20: SUPCOLL | B20: =CORREL('Raw Data (0-4 Scores)'!N2:N106,'Raw Data (0-4 Scores)'!J2:J106) -> 0.41031836 | C20: =CORREL('Raw Data (0-4 Scores)'!N2:N106,'Raw Data (0-4 Scores)'!K2:K106) -> 0.38036517 | D20: =CORREL('Raw Data (0-4 Scores)'!N2:N106,'Raw Data (0-4 Scores)'!L2:L106) -> 0.53720152 | E20: =CORREL('Raw Data (0-4 Scores)'!N2:N106,'Raw Data (0-4 Scores)'!M2:M106) -> 0.6184411 | F20: =CORREL('Raw Data (0-4 Scores)'!N2:N106,'Raw Data (0-4 Scores)'!N2:N106) -> 1 | G20: =CORREL('Raw Data (0-4 Scores)'!N2:N106,'Raw Data (0-4 Scores)'!O2:O106) -> 0.42037975 | H20: =CORREL('Raw Data (0-4 Scores)'!N2:N106,'Raw Data (0-4 Scores)'!P2:P106) -> 0.6652512
A21: SUPDIV | B21: =CORREL('Raw Data (0-4 Scores)'!O2:O106,'Raw Data (0-4 Scores)'!J2:J106) -> 0.27637101 | C21: =CORREL('Raw Data (0-4 Scores)'!O2:O106,'Raw Data (0-4 Scores)'!K2:K106) -> 0.48197541 | D21: =CORREL('Raw Data (0-4 Scores)'!O2:O106,'Raw Data (0-4 Scores)'!L2:L106) -> 0.28096397 | E21: =CORREL('Raw Data (0-4 Scores)'!O2:O106,'Raw Data (0-4 Scores)'!M2:M106) -> 0.60272699 | F21: =CORREL('Raw Data (0-4 Scores)'!O2:O106,'Raw Data (0-4 Scores)'!N2:N106) -> 0.42037975 | G21: =CORREL('Raw Data (0-4 Scores)'!O2:O106,'Raw Data (0-4 Scores)'!O2:O106) -> 1 | H21: =CORREL('Raw Data (0-4 Scores)'!O2:O106,'Raw Data (0-4 Scores)'!P2:P106) -> 0.62922509
A22: SCR | B22: =CORREL('Raw Data (0-4 Scores)'!P2:P106,'Raw Data (0-4 Scores)'!J2:J106) -> 0.4526654 | C22: =CORREL('Raw Data (0-4 Scores)'!P2:P106,'Raw Data (0-4 Scores)'!K2:K106) -> 0.44642969 | D22: =CORREL('Raw Data (0-4 Scores)'!P2:P106,'Raw Data (0-4 Scores)'!L2:L106) -> 0.39243361 | E22: =CORREL('Raw Data (0-4 Scores)'!P2:P106,'Raw Data (0-4 Scores)'!M2:M106) -> 0.66462919 | F22: =CORREL('Raw Data (0-4 Scores)'!P2:P106,'Raw Data (0-4 Scores)'!N2:N106) -> 0.6652512 | G22: =CORREL('Raw Data (0-4 Scores)'!P2:P106,'Raw Data (0-4 Scores)'!O2:O106) -> 0.62922509 | H22: =CORREL('Raw Data (0-4 Scores)'!P2:P106,'Raw Data (0-4 Scores)'!P2:P106) -> 1

Sheet Analysis Settings
A1: SETTINGS - thresholds and calibration anchors (v2)
A2: Blue cells on yellow are inputs; every v2 sheet recalculates when they change.
A3: Truth-table retention thresholds (corrected rule)
A4: Min frequency (firm-years) | B4: 2 | C4: Guideline (Pappas & Woodside 2021): 2 for samples under 150 cases; the draft paper says 1.
A5: Min distinct firms per row | B5: 2 | C5: Added: frequency counts firm-years, so a row can rest on one firm observed in several years.
A6: Min raw consistency | B6: 0.8 | C6: Guideline: 0.75 minimum, 0.80 suggested; 0.90 is a natural break in this data (see Threshold Sensitivity).
A7: Min PRI | B7: 0.5 | C7: Guideline: 0.50 minimum. The original truth table applied no PRI condition.
A8: Log-odds at full membership / full non-membership | B8: =LN(19) -> 2.944439 | C8: ln(0.95/0.05) = 2.944; reproduces the delivered Fuzzy Scores (Source) (max difference 0.001, at crossover cells only).
A9: Membership assigned to a case exactly at the crossover | B9: 0.501 | C9: Same 0.5 -> 0.501 adjustment as the delivered Fuzzy Scores (Source) (Fiss 2011), so no case is dropped at exactly 0.5.
A10: Original rule for comparison: min frequency | B10: 2 | C10: Reverse-engineered from the delivered Retained_conventional column (matches all 64 rows).
A11: Original rule for comparison: min raw consistency | B11: 0.8
A13: Calibration anchors (e = full non-membership, c = crossover, i = full membership)
A14: Variable | B14: Pctl e (5th) | C14: Pctl c (50th) | D14: Pctl i (95th) | E14: Rubric e | F14: Rubric c | G14: Rubric i | H14: Pctl matches Calibration Anchors?
A15: AICAP | B15: =PERCENTILE('Raw Data (0-4 Scores)'!$J$2:$J$106,0.05) -> 0.5 | C15: =PERCENTILE('Raw Data (0-4 Scores)'!$J$2:$J$106,0.5) -> 2.03 | D15: =PERCENTILE('Raw Data (0-4 Scores)'!$J$2:$J$106,0.95) -> 4 | E15: 1 | F15: 2 | G15: 3 | H15: =IF(AND(ABS(B15-'Calibration Anchors'!B2)<0.0005,ABS(C15-'Calibration Anchors'!C2)<0.0005,ABS(D15-'Calibration Anchors'!D2)<0.0005),"OK","CHECK") -> OK
A16: AIGOV | B16: =PERCENTILE('Raw Data (0-4 Scores)'!$K$2:$K$106,0.05) -> 0.47 | C16: =PERCENTILE('Raw Data (0-4 Scores)'!$K$2:$K$106,0.5) -> 1.14 | D16: =PERCENTILE('Raw Data (0-4 Scores)'!$K$2:$K$106,0.95) -> 3.144 | E16: 1 | F16: 2 | G16: 3 | H16: =IF(AND(ABS(B16-'Calibration Anchors'!B3)<0.0005,ABS(C16-'Calibration Anchors'!C3)<0.0005,ABS(D16-'Calibration Anchors'!D3)<0.0005),"OK","CHECK") -> OK
A17: SUSSRC | B17: =PERCENTILE('Raw Data (0-4 Scores)'!$L$2:$L$106,0.05) -> 0.962 | C17: =PERCENTILE('Raw Data (0-4 Scores)'!$L$2:$L$106,0.5) -> 2.85 | D17: =PERCENTILE('Raw Data (0-4 Scores)'!$L$2:$L$106,0.95) -> 4 | E17: 1 | F17: 2 | G17: 3 | H17: =IF(AND(ABS(B17-'Calibration Anchors'!B4)<0.0005,ABS(C17-'Calibration Anchors'!C4)<0.0005,ABS(D17-'Calibration Anchors'!D4)<0.0005),"OK","CHECK") -> OK
A18: DIGVIS | B18: =PERCENTILE('Raw Data (0-4 Scores)'!$M$2:$M$106,0.05) -> 0.694 | C18: =PERCENTILE('Raw Data (0-4 Scores)'!$M$2:$M$106,0.5) -> 1.9 | D18: =PERCENTILE('Raw Data (0-4 Scores)'!$M$2:$M$106,0.95) -> 3.47 | E18: 1 | F18: 2 | G18: 3 | H18: =IF(AND(ABS(B18-'Calibration Anchors'!B5)<0.0005,ABS(C18-'Calibration Anchors'!C5)<0.0005,ABS(D18-'Calibration Anchors'!D5)<0.0005),"OK","CHECK") -> OK
A19: SUPCOLL | B19: =PERCENTILE('Raw Data (0-4 Scores)'!$N$2:$N$106,0.05) -> 0.942 | C19: =PERCENTILE('Raw Data (0-4 Scores)'!$N$2:$N$106,0.5) -> 2.36 | D19: =PERCENTILE('Raw Data (0-4 Scores)'!$N$2:$N$106,0.95) -> 4 | E19: 1 | F19: 2 | G19: 3 | H19: =IF(AND(ABS(B19-'Calibration Anchors'!B6)<0.0005,ABS(C19-'Calibration Anchors'!C6)<0.0005,ABS(D19-'Calibration Anchors'!D6)<0.0005),"OK","CHECK") -> OK
A20: SUPDIV | B20: =PERCENTILE('Raw Data (0-4 Scores)'!$O$2:$O$106,0.05) -> 0.794 | C20: =PERCENTILE('Raw Data (0-4 Scores)'!$O$2:$O$106,0.5) -> 1.93 | D20: =PERCENTILE('Raw Data (0-4 Scores)'!$O$2:$O$106,0.95) -> 4 | E20: 1 | F20: 2 | G20: 3 | H20: =IF(AND(ABS(B20-'Calibration Anchors'!B7)<0.0005,ABS(C20-'Calibration Anchors'!C7)<0.0005,ABS(D20-'Calibration Anchors'!D7)<0.0005),"OK","CHECK") -> OK
A21: SCR | B21: =PERCENTILE('Raw Data (0-4 Scores)'!$P$2:$P$106,0.05) -> 0.96 | C21: =PERCENTILE('Raw Data (0-4 Scores)'!$P$2:$P$106,0.5) -> 2.43 | D21: =PERCENTILE('Raw Data (0-4 Scores)'!$P$2:$P$106,0.95) -> 3.756 | E21: 1 | F21: 2 | G21: 3 | H21: =IF(AND(ABS(B21-'Calibration Anchors'!B8)<0.0005,ABS(C21-'Calibration Anchors'!C8)<0.0005,ABS(D21-'Calibration Anchors'!D8)<0.0005),"OK","CHECK") -> OK
A23: Rubric anchors 1 / 2 / 3 follow the Scoring Method rubric: 1 = very limited, 2 = moderate, 3 = substantial. The percentile variant uses the delivered fuzzy values, so it reproduces the original workbook.

Sheet Fuzzy Scores - Percentile
A1: Company | B1: Year | C1: fz_AICAP | D1: fz_AIGOV | E1: fz_SUSSRC | F1: fz_DIGVIS | G1: fz_SUPCOLL | H1: fz_SUPDIV | I1: fz_SCR | J1: min(SCR,1-SCR)
A2: ='Fuzzy Scores (Source)'!A2 -> AEM Holdings | B2: ='Fuzzy Scores (Source)'!C2 -> 2023 | C2: ='Fuzzy Scores (Source)'!D2 -> 0.592343 | D2: ='Fuzzy Scores (Source)'!E2 -> 0.037253 | E2: ='Fuzzy Scores (Source)'!F2 -> 0.148464 | F2: ='Fuzzy Scores (Source)'!G2 -> 0.273568 | G2: ='Fuzzy Scores (Source)'!H2 -> 0.032779 | H2: ='Fuzzy Scores (Source)'!I2 -> 0.143265 | I2: ='Fuzzy Scores (Source)'!J2 -> 0.167644 | J2: =MIN(I2,1-I2) -> 0.167644
A3: ='Fuzzy Scores (Source)'!A3 -> AEM Holdings | B3: ='Fuzzy Scores (Source)'!C3 -> 2024 | C3: ='Fuzzy Scores (Source)'!D3 -> 0.819 | D3: ='Fuzzy Scores (Source)'!E3 -> 0.24184 | E3: ='Fuzzy Scores (Source)'!F3 -> 0.162801 | F3: ='Fuzzy Scores (Source)'!G3 -> 0.463443 | G3: ='Fuzzy Scores (Source)'!H3 -> 0.047874 | H3: ='Fuzzy Scores (Source)'!I3 -> 0.063233 | I3: ='Fuzzy Scores (Source)'!J3 -> 0.242004 | J3: =MIN(I3,1-I3) -> 0.242004
A4: ='Fuzzy Scores (Source)'!A4 -> AEM Holdings | B4: ='Fuzzy Scores (Source)'!C4 -> 2025 | C4: ='Fuzzy Scores (Source)'!D4 -> 0.833995 | D4: ='Fuzzy Scores (Source)'!E4 -> 0.434459 | E4: ='Fuzzy Scores (Source)'!F4 -> 0.223108 | F4: ='Fuzzy Scores (Source)'!G4 -> 0.737205 | G4: ='Fuzzy Scores (Source)'!H4 -> 0.08571 | H4: ='Fuzzy Scores (Source)'!I4 -> 0.298314 | I4: ='Fuzzy Scores (Source)'!J4 -> 0.363352 | J4: =MIN(I4,1-I4) -> 0.363352
A5: ='Fuzzy Scores (Source)'!A5 -> ASE Technology Holding | B5: ='Fuzzy Scores (Source)'!C5 -> 2023 | C5: ='Fuzzy Scores (Source)'!D5 -> 0.276431 | D5: ='Fuzzy Scores (Source)'!E5 -> 0.08188 | E5: ='Fuzzy Scores (Source)'!F5 -> 0.472735 | F5: ='Fuzzy Scores (Source)'!G5 -> 0.346426 | G5: ='Fuzzy Scores (Source)'!H5 -> 0.897745 | H5: ='Fuzzy Scores (Source)'!I5 -> 0.574127 | I5: ='Fuzzy Scores (Source)'!J5 -> 0.780007 | J5: =MIN(I5,1-I5) -> 0.219993
A6: ='Fuzzy Scores (Source)'!A6 -> ASE Technology Holding | B6: ='Fuzzy Scores (Source)'!C6 -> 2024 | C6: ='Fuzzy Scores (Source)'!D6 -> 0.507473 | D6: ='Fuzzy Scores (Source)'!E6 -> 0.445286 | E6: ='Fuzzy Scores (Source)'!F6 -> 0.677545 | F6: ='Fuzzy Scores (Source)'!G6 -> 0.556027 | G6: ='Fuzzy Scores (Source)'!H6 -> 0.95 | H6: ='Fuzzy Scores (Source)'!I6 -> 0.448346 | I6: ='Fuzzy Scores (Source)'!J6 -> 0.748017 | J6: =MIN(I6,1-I6) -> 0.251983
A7: ='Fuzzy Scores (Source)'!A7 -> ASE Technology Holding | B7: ='Fuzzy Scores (Source)'!C7 -> 2025 | C7: ='Fuzzy Scores (Source)'!D7 -> 0.447274 | D7: ='Fuzzy Scores (Source)'!E7 -> 0.576531 | E7: ='Fuzzy Scores (Source)'!F7 -> 0.648965 | F7: ='Fuzzy Scores (Source)'!G7 -> 0.565266 | G7: ='Fuzzy Scores (Source)'!H7 -> 0.95 | H7: ='Fuzzy Scores (Source)'!I7 -> 0.62862 | I7: ='Fuzzy Scores (Source)'!J7 -> 0.852485 | J7: =MIN(I7,1-I7) -> 0.147515
A8: ='Fuzzy Scores (Source)'!A8 -> Advanced Micro Devices | B8: ='Fuzzy Scores (Source)'!C8 -> 2023 | C8: ='Fuzzy Scores (Source)'!D8 -> 0.882649 | D8: ='Fuzzy Scores (Source)'!E8 -> 0.915308 | E8: ='Fuzzy Scores (Source)'!F8 -> 0.551029 | F8: ='Fuzzy Scores (Source)'!G8 -> 0.487795 | G8: ='Fuzzy Scores (Source)'!H8 -> 0.610365 | H8: ='Fuzzy Scores (Source)'!I8 -> 0.448346 | I8: ='Fuzzy Scores (Source)'!J8 -> 0.783794 | J8: =MIN(I8,1-I8) -> 0.216206
A9: ='Fuzzy Scores (Source)'!A9 -> Advanced Micro Devices | B9: ='Fuzzy Scores (Source)'!C9 -> 2024 | C9: ='Fuzzy Scores (Source)'!D9 -> 0.95 | D9: ='Fuzzy Scores (Source)'!E9 -> 0.913002 | E9: ='Fuzzy Scores (Source)'!F9 -> 0.671926 | F9: ='Fuzzy Scores (Source)'!G9 -> 0.565266 | G9: ='Fuzzy Scores (Source)'!H9 -> 0.790607 | H9: ='Fuzzy Scores (Source)'!I9 -> 0.48057 | I9: ='Fuzzy Scores (Source)'!J9 -> 0.857983 | J9: =MIN(I9,1-I9) -> 0.142017
A10: ='Fuzzy Scores (Source)'!A10 -> Advanced Micro Devices | B10: ='Fuzzy Scores (Source)'!C10 -> 2025 | C10: ='Fuzzy Scores (Source)'!D10 -> 0.95 | D10: ='Fuzzy Scores (Source)'!E10 -> 0.953767 | E10: ='Fuzzy Scores (Source)'!F10 -> 0.778093 | F10: ='Fuzzy Scores (Source)'!G10 -> 0.754964 | G10: ='Fuzzy Scores (Source)'!H10 -> 0.790607 | H10: ='Fuzzy Scores (Source)'!I10 -> 0.645066 | I10: ='Fuzzy Scores (Source)'!J10 -> 0.902079 | J10: =MIN(I10,1-I10) -> 0.097921
A11: ='Fuzzy Scores (Source)'!A11 -> Analog Devices | B11: ='Fuzzy Scores (Source)'!C11 -> 2023 | C11: ='Fuzzy Scores (Source)'!D11 -> 0.056801 | D11: ='Fuzzy Scores (Source)'!E11 -> 0.108182 | E11: ='Fuzzy Scores (Source)'!F11 -> 0.496101 | F11: ='Fuzzy Scores (Source)'!G11 -> 0.335454 | G11: ='Fuzzy Scores (Source)'!H11 -> 0.192668 | H11: ='Fuzzy Scores (Source)'!I11 -> 0.501 | I11: ='Fuzzy Scores (Source)'!J11 -> 0.680264 | J11: =MIN(I11,1-I11) -> 0.319736
A12: ='Fuzzy Scores (Source)'!A12 -> Analog Devices | B12: ='Fuzzy Scores (Source)'!C12 -> 2024 | C12: ='Fuzzy Scores (Source)'!D12 -> 0.13392 | D12: ='Fuzzy Scores (Source)'!E12 -> 0.249989 | E12: ='Fuzzy Scores (Source)'!F12 -> 0.512799 | F12: ='Fuzzy Scores (Source)'!G12 -> 0.537439 | G12: ='Fuzzy Scores (Source)'!H12 -> 0.358608 | H12: ='Fuzzy Scores (Source)'!I12 -> 0.510667 | I12: ='Fuzzy Scores (Source)'!J12 -> 0.73091 | J12: =MIN(I12,1-I12) -> 0.26909
A13: ='Fuzzy Scores (Source)'!A13 -> Analog Devices | B13: ='Fuzzy Scores (Source)'!C13 -> 2025 | C13: ='Fuzzy Scores (Source)'!D13 -> 0.20951 | D13: ='Fuzzy Scores (Source)'!E13 -> 0.562122 | E13: ='Fuzzy Scores (Source)'!F13 -> 0.61322 | F13: ='Fuzzy Scores (Source)'!G13 -> 0.781648 | G13: ='Fuzzy Scores (Source)'!H13 -> 0.474067 | H13: ='Fuzzy Scores (Source)'!I13 -> 0.67067 | I13: ='Fuzzy Scores (Source)'!J13 -> 0.852485 | J13: =MIN(I13,1-I13) -> 0.147515
... A106: ='Fuzzy Scores (Source)'!A106 -> onsemi | B106: ='Fuzzy Scores (Source)'!C106 -> 2025 | C106: ='Fuzzy Scores (Source)'!D106 -> 0.606696 | D106: ='Fuzzy Scores (Source)'!E106 -> 0.672595 | E106: ='Fuzzy Scores (Source)'!F106 -> 0.95 | F106: ='Fuzzy Scores (Source)'!G106 -> 0.546749 | G106: ='Fuzzy Scores (Source)'!H106 -> 0.752714 | H106: ='Fuzzy Scores (Source)'!I106 -> 0.422863 | I106: ='Fuzzy Scores (Source)'!J106 -> 0.363352 | J106: =MIN(I106,1-I106) -> 0.363352

Sheet Fuzzy Scores - Rubric
A1: Company | B1: Year | C1: fz_AICAP | D1: fz_AIGOV | E1: fz_SUSSRC | F1: fz_DIGVIS | G1: fz_SUPCOLL | H1: fz_SUPDIV | I1: fz_SCR | J1: min(SCR,1-SCR)
A2: ='Raw Data (0-4 Scores)'!A2 -> AEM Holdings | B2: ='Raw Data (0-4 Scores)'!E2 -> 2023 | C2: =IF('Raw Data (0-4 Scores)'!J2='Analysis Settings'!$F$15,'Analysis Settings'!$B$9,1/(1+EXP(-'Analysis Settings'!$B$8*IF('Raw Data (0-4 Scores)'!J2>'Analysis Settings'!$F$15,('Raw Data (0-4 Scores)'!J2-'Analysis Settings'!$F$15)/('Analysis Settings'!$G$15-'Analysis Settings'!$F$15),('Raw Data (0-4 Scores)'!J2-'Analysis Settings'!$F$15)/('Analysis Settings'!$F$15-'Analysis Settings'!$E$15))))) -> 0.69517863 | D2: =IF('Raw Data (0-4 Scores)'!K2='Analysis Settings'!$F$16,'Analysis Settings'!$B$9,1/(1+EXP(-'Analysis Settings'!$B$8*IF('Raw Data (0-4 Scores)'!K2>'Analysis Settings'!$F$16,('Raw Data (0-4 Scores)'!K2-'Analysis Settings'!$F$16)/('Analysis Settings'!$G$16-'Analysis Settings'!$F$16),('Raw Data (0-4 Scores)'!K2-'Analysis Settings'!$F$16)/('Analysis Settings'!$F$16-'Analysis Settings'!$E$16))))) -> 0.0089146703 | E2: =IF('Raw Data (0-4 Scores)'!L2='Analysis Settings'!$F$17,'Analysis Settings'!$B$9,1/(1+EXP(-'Analysis Settings'!$B$8*IF('Raw Data (0-4 Scores)'!L2>'Analysis Settings'!$F$17,('Raw Data (0-4 Scores)'!L2-'Analysis Settings'!$F$17)/('Analysis Settings'!$G$17-'Analysis Settings'!$F$17),('Raw Data (0-4 Scores)'!L2-'Analysis Settings'!$F$17)/('Analysis Settings'!$F$17-'Analysis Settings'!$E$17))))) -> 0.3110964 | F2: =IF('Raw Data (0-4 Scores)'!M2='Analysis Settings'!$F$18,'Analysis Settings'!$B$9,1/(1+EXP(-'Analysis Settings'!$B$8*IF('Raw Data (0-4 Scores)'!M2>'Analysis Settings'!$F$18,('Raw Data (0-4 Scores)'!M2-'Analysis Settings'!$F$18)/('Analysis Settings'!$G$18-'Analysis Settings'!$F$18),('Raw Data (0-4 Scores)'!M2-'Analysis Settings'!$F$18)/('Analysis Settings'!$F$18-'Analysis Settings'!$E$18))))) -> 0.1866055 | G2: =IF('Raw Data (0-4 Scores)'!N2='Analysis Settings'!$F$19,'Analysis Settings'!$B$9,1/(1+EXP(-'Analysis Settings'!$B$8*IF('Raw Data (0-4 Scores)'!N2>'Analysis Settings'!$F$19,('Raw Data (0-4 Scores)'!N2-'Analysis Settings'!$F$19)/('Analysis Settings'!$G$19-'Analysis Settings'!$F$19),('Raw Data (0-4 Scores)'!N2-'Analysis Settings'!$F$19)/('Analysis Settings'!$F$19-'Analysis Settings'!$E$19))))) -> 0.02321569 | H2: =IF('Raw Data (0-4 Scores)'!O2='Analysis Settings'!$F$20,'Analysis Settings'!$B$9,1/(1+EXP(-'Analysis Settings'!$B$8*IF('Raw Data (0-4 Scores)'!O2>'Analysis Settings'!$F$20,('Raw Data (0-4 Scores)'!O2-'Analysis Settings'!$F$20)/('Analysis Settings'!$G$20-'Analysis Settings'!$F$20),('Raw Data (0-4 Scores)'!O2-'Analysis Settings'!$F$20)/('Analysis Settings'!$F$20-'Analysis Settings'!$E$20))))) -> 0.096409317 | I2: =IF('Raw Data (0-4 Scores)'!P2='Analysis Settings'!$F$21,'Analysis Settings'!$B$9,1/(1+EXP(-'Analysis Settings'!$B$8*IF('Raw Data (0-4 Scores)'!P2>'Analysis Settings'!$F$21,('Raw Data (0-4 Scores)'!P2-'Analysis Settings'!$F$21)/('Analysis Settings'!$G$21-'Analysis Settings'!$F$21),('Raw Data (0-4 Scores)'!P2-'Analysis Settings'!$F$21)/('Analysis Settings'!$F$21-'Analysis Settings'!$E$21))))) -> 0.25172329 | J2: =MIN(I2,1-I2) -> 0.25172329
A3: ='Raw Data (0-4 Scores)'!A3 -> AEM Holdings | B3: ='Raw Data (0-4 Scores)'!E3 -> 2024 | C3: =IF('Raw Data (0-4 Scores)'!J3='Analysis Settings'!$F$15,'Analysis Settings'!$B$9,1/(1+EXP(-'Analysis Settings'!$B$8*IF('Raw Data (0-4 Scores)'!J3>'Analysis Settings'!$F$15,('Raw Data (0-4 Scores)'!J3-'Analysis Settings'!$F$15)/('Analysis Settings'!$G$15-'Analysis Settings'!$F$15),('Raw Data (0-4 Scores)'!J3-'Analysis Settings'!$F$15)/('Analysis Settings'!$F$15-'Analysis Settings'!$E$15))))) -> 0.95530703 | D3: =IF('Raw Data (0-4 Scores)'!K3='Analysis Settings'!$F$16,'Analysis Settings'!$B$9,1/(1+EXP(-'Analysis Settings'!$B$8*IF('Raw Data (0-4 Scores)'!K3>'Analysis Settings'!$F$16,('Raw Data (0-4 Scores)'!K3-'Analysis Settings'!$F$16)/('Analysis Settings'!$G$16-'Analysis Settings'!$F$16),('Raw Data (0-4 Scores)'!K3-'Analysis Settings'!$F$16)/('Analysis Settings'!$F$16-'Analysis Settings'!$E$16))))) -> 0.035647714 | E3: =IF('Raw Data (0-4 Scores)'!L3='Analysis Settings'!$F$17,'Analysis Settings'!$B$9,1/(1+EXP(-'Analysis Settings'!$B$8*IF('Raw Data (0-4 Scores)'!L3>'Analysis Settings'!$F$17,('Raw Data (0-4 Scores)'!L3-'Analysis Settings'!$F$17)/('Analysis Settings'!$G$17-'Analysis Settings'!$F$17),('Raw Data (0-4 Scores)'!L3-'Analysis Settings'!$F$17)/('Analysis Settings'!$F$17-'Analysis Settings'!$E$17))))) -> 0.35689009 | F3: =IF('Raw Data (0-4 Scores)'!M3='Analysis Settings'!$F$18,'Analysis Settings'!$B$9,1/(1+EXP(-'Analysis Settings'!$B$8*IF('Raw Data (0-4 Scores)'!M3>'Analysis Settings'!$F$18,('Raw Data (0-4 Scores)'!M3-'Analysis Settings'!$F$18)/('Analysis Settings'!$G$18-'Analysis Settings'!$F$18),('Raw Data (0-4 Scores)'!M3-'Analysis Settings'!$F$18)/('Analysis Settings'!$F$18-'Analysis Settings'!$E$18))))) -> 0.3843535 | G3: =IF('Raw Data (0-4 Scores)'!N3='Analysis Settings'!$F$19,'Analysis Settings'!$B$9,1/(1+EXP(-'Analysis Settings'!$B$8*IF('Raw Data (0-4 Scores)'!N3>'Analysis Settings'!$F$19,('Raw Data (0-4 Scores)'!N3-'Analysis Settings'!$F$19)/('Analysis Settings'!$G$19-'Analysis Settings'!$F$19),('Raw Data (0-4 Scores)'!N3-'Analysis Settings'!$F$19)/('Analysis Settings'!$F$19-'Analysis Settings'!$E$19))))) -> 0.03992556 | H3: =IF('Raw Data (0-4 Scores)'!O3='Analysis Settings'!$F$20,'Analysis Settings'!$B$9,1/(1+EXP(-'Analysis Settings'!$B$8*IF('Raw Data (0-4 Scores)'!O3>'Analysis Settings'!$F$20,('Raw Data (0-4 Scores)'!O3-'Analysis Settings'!$F$20)/('Analysis Settings'!$G$20-'Analysis Settings'!$F$20),('Raw Data (0-4 Scores)'!O3-'Analysis Settings'!$F$20)/('Analysis Settings'!$F$20-'Analysis Settings'!$E$20))))) -> 0.036673878 | I3: =IF('Raw Data (0-4 Scores)'!P3='Analysis Settings'!$F$21,'Analysis Settings'!$B$9,1/(1+EXP(-'Analysis Settings'!$B$8*IF('Raw Data (0-4 Scores)'!P3>'Analysis Settings'!$F$21,('Raw Data (0-4 Scores)'!P3-'Analysis Settings'!$F$21)/('Analysis Settings'!$G$21-'Analysis Settings'!$F$21),('Raw Data (0-4 Scores)'!P3-'Analysis Settings'!$F$21)/('Analysis Settings'!$F$21-'Analysis Settings'!$E$21))))) -> 0.39837958 | J3: =MIN(I3,1-I3) -> 0.39837958
A4: ='Raw Data (0-4 Scores)'!A4 -> AEM Holdings | B4: ='Raw Data (0-4 Scores)'!E4 -> 2025 | C4: =IF('Raw Data (0-4 Scores)'!J4='Analysis Settings'!$F$15,'Analysis Settings'!$B$9,1/(1+EXP(-'Analysis Settings'!$B$8*IF('Raw Data (0-4 Scores)'!J4>'Analysis Settings'!$F$15,('Raw Data (0-4 Scores)'!J4-'Analysis Settings'!$F$15)/('Analysis Settings'!$G$15-'Analysis Settings'!$F$15),('Raw Data (0-4 Scores)'!J4-'Analysis Settings'!$F$15)/('Analysis Settings'!$F$15-'Analysis Settings'!$E$15))))) -> 0.96332612 | D4: =IF('Raw Data (0-4 Scores)'!K4='Analysis Settings'!$F$16,'Analysis Settings'!$B$9,1/(1+EXP(-'Analysis Settings'!$B$8*IF('Raw Data (0-4 Scores)'!K4>'Analysis Settings'!$F$16,('Raw Data (0-4 Scores)'!K4-'Analysis Settings'!$F$16)/('Analysis Settings'!$G$16-'Analysis Settings'!$F$16),('Raw Data (0-4 Scores)'!K4-'Analysis Settings'!$F$16)/('Analysis Settings'!$F$16-'Analysis Settings'!$E$16))))) -> 0.062451171 | E4: =IF('Raw Data (0-4 Scores)'!L4='Analysis Settings'!$F$17,'Analysis Settings'!$B$9,1/(1+EXP(-'Analysis Settings'!$B$8*IF('Raw Data (0-4 Scores)'!L4>'Analysis Settings'!$F$17,('Raw Data (0-4 Scores)'!L4-'Analysis Settings'!$F$17)/('Analysis Settings'!$G$17-'Analysis Settings'!$F$17),('Raw Data (0-4 Scores)'!L4-'Analysis Settings'!$F$17)/('Analysis Settings'!$F$17-'Analysis Settings'!$E$17))))) -> 0.53673915 | F4: =IF('Raw Data (0-4 Scores)'!M4='Analysis Settings'!$F$18,'Analysis Settings'!$B$9,1/(1+EXP(-'Analysis Settings'!$B$8*IF('Raw Data (0-4 Scores)'!M4>'Analysis Settings'!$F$18,('Raw Data (0-4 Scores)'!M4-'Analysis Settings'!$F$18)/('Analysis Settings'!$G$18-'Analysis Settings'!$F$18),('Raw Data (0-4 Scores)'!M4-'Analysis Settings'!$F$18)/('Analysis Settings'!$F$18-'Analysis Settings'!$E$18))))) -> 0.79001197 | G4: =IF('Raw Data (0-4 Scores)'!N4='Analysis Settings'!$F$19,'Analysis Settings'!$B$9,1/(1+EXP(-'Analysis Settings'!$B$8*IF('Raw Data (0-4 Scores)'!N4>'Analysis Settings'!$F$19,('Raw Data (0-4 Scores)'!N4-'Analysis Settings'!$F$19)/('Analysis Settings'!$G$19-'Analysis Settings'!$F$19),('Raw Data (0-4 Scores)'!N4-'Analysis Settings'!$F$19)/('Analysis Settings'!$F$19-'Analysis Settings'!$E$19))))) -> 0.091399757 | H4: =IF('Raw Data (0-4 Scores)'!O4='Analysis Settings'!$F$20,'Analysis Settings'!$B$9,1/(1+EXP(-'Analysis Settings'!$B$8*IF('Raw Data (0-4 Scores)'!O4>'Analysis Settings'!$F$20,('Raw Data (0-4 Scores)'!O4-'Analysis Settings'!$F$20)/('Analysis Settings'!$G$20-'Analysis Settings'!$F$20),('Raw Data (0-4 Scores)'!O4-'Analysis Settings'!$F$20)/('Analysis Settings'!$F$20-'Analysis Settings'!$E$20))))) -> 0.23545239 | I4: =IF('Raw Data (0-4 Scores)'!P4='Analysis Settings'!$F$21,'Analysis Settings'!$B$9,1/(1+EXP(-'Analysis Settings'!$B$8*IF('Raw Data (0-4 Scores)'!P4>'Analysis Settings'!$F$21,('Raw Data (0-4 Scores)'!P4-'Analysis Settings'!$F$21)/('Analysis Settings'!$G$21-'Analysis Settings'!$F$21),('Raw Data (0-4 Scores)'!P4-'Analysis Settings'!$F$21)/('Analysis Settings'!$F$21-'Analysis Settings'!$E$21))))) -> 0.6086559 | J4: =MIN(I4,1-I4) -> 0.3913441
A5: ='Raw Data (0-4 Scores)'!A5 -> ASE Technology Holding | B5: ='Raw Data (0-4 Scores)'!E5 -> 2023 | C5: =IF('Raw Data (0-4 Scores)'!J5='Analysis Settings'!$F$15,'Analysis Settings'!$B$9,1/(1+EXP(-'Analysis Settings'!$B$8*IF('Raw Data (0-4 Scores)'!J5>'Analysis Settings'!$F$15,('Raw Data (0-4 Scores)'!J5-'Analysis Settings'!$F$15)/('Analysis Settings'!$G$15-'Analysis Settings'!$F$15),('Raw Data (0-4 Scores)'!J5-'Analysis Settings'!$F$15)/('Analysis Settings'!$F$15-'Analysis Settings'!$E$15))))) -> 0.20038556 | D5: =IF('Raw Data (0-4 Scores)'!K5='Analysis Settings'!$F$16,'Analysis Settings'!$B$9,1/(1+EXP(-'Analysis Settings'!$B$8*IF('Raw Data (0-4 Scores)'!K5>'Analysis Settings'!$F$16,('Raw Data (0-4 Scores)'!K5-'Analysis Settings'!$F$16)/('Analysis Settings'!$G$16-'Analysis Settings'!$F$16),('Raw Data (0-4 Scores)'!K5-'Analysis Settings'!$F$16)/('Analysis Settings'!$F$16-'Analysis Settings'!$E$16))))) -> 0.01549443 | E5: =IF('Raw Data (0-4 Scores)'!L5='Analysis Settings'!$F$17,'Analysis Settings'!$B$9,1/(1+EXP(-'Analysis Settings'!$B$8*IF('Raw Data (0-4 Scores)'!L5>'Analysis Settings'!$F$17,('Raw Data (0-4 Scores)'!L5-'Analysis Settings'!$F$17)/('Analysis Settings'!$G$17-'Analysis Settings'!$F$17),('Raw Data (0-4 Scores)'!L5-'Analysis Settings'!$F$17)/('Analysis Settings'!$F$17-'Analysis Settings'!$E$17))))) -> 0.90860024 | F5: =IF('Raw Data (0-4 Scores)'!M5='Analysis Settings'!$F$18,'Analysis Settings'!$B$9,1/(1+EXP(-'Analysis Settings'!$B$8*IF('Raw Data (0-4 Scores)'!M5>'Analysis Settings'!$F$18,('Raw Data (0-4 Scores)'!M5-'Analysis Settings'!$F$18)/('Analysis Settings'!$G$18-'Analysis Settings'!$F$18),('Raw Data (0-4 Scores)'!M5-'Analysis Settings'!$F$18)/('Analysis Settings'!$F$18-'Analysis Settings'!$E$18))))) -> 0.25730983 | G5: =IF('Raw Data (0-4 Scores)'!N5='Analysis Settings'!$F$19,'Analysis Settings'!$B$9,1/(1+EXP(-'Analysis Settings'!$B$8*IF('Raw Data (0-4 Scores)'!N5>'Analysis Settings'!$F$19,('Raw Data (0-4 Scores)'!N5-'Analysis Settings'!$F$19)/('Analysis Settings'!$G$19-'Analysis Settings'!$F$19),('Raw Data (0-4 Scores)'!N5-'Analysis Settings'!$F$19)/('Analysis Settings'!$F$19-'Analysis Settings'!$E$19))))) -> 0.99027005 | H5: =IF('Raw Data (0-4 Scores)'!O5='Analysis Settings'!$F$20,'Analysis Settings'!$B$9,1/(1+EXP(-'Analysis Settings'!$B$8*IF('Raw Data (0-4 Scores)'!O5>'Analysis Settings'!$F$20,('Raw Data (0-4 Scores)'!O5-'Analysis Settings'!$F$20)/('Analysis Settings'!$G$20-'Analysis Settings'!$F$20),('Raw Data (0-4 Scores)'!O5-'Analysis Settings'!$F$20)/('Analysis Settings'!$F$20-'Analysis Settings'!$E$20))))) -> 0.60162042 | I5: =IF('Raw Data (0-4 Scores)'!P5='Analysis Settings'!$F$21,'Analysis Settings'!$B$9,1/(1+EXP(-'Analysis Settings'!$B$8*IF('Raw Data (0-4 Scores)'!P5>'Analysis Settings'!$F$21,('Raw Data (0-4 Scores)'!P5-'Analysis Settings'!$F$21)/('Analysis Settings'!$G$21-'Analysis Settings'!$F$21),('Raw Data (0-4 Scores)'!P5-'Analysis Settings'!$F$21)/('Analysis Settings'!$F$21-'Analysis Settings'!$E$21))))) -> 0.95 | J5: =MIN(I5,1-I5) -> 0.05
A6: ='Raw Data (0-4 Scores)'!A6 -> ASE Technology Holding | B6: ='Raw Data (0-4 Scores)'!E6 -> 2024 | C6: =IF('Raw Data (0-4 Scores)'!J6='Analysis Settings'!$F$15,'Analysis Settings'!$B$9,1/(1+EXP(-'Analysis Settings'!$B$8*IF('Raw Data (0-4 Scores)'!J6>'Analysis Settings'!$F$15,('Raw Data (0-4 Scores)'!J6-'Analysis Settings'!$F$15)/('Analysis Settings'!$G$15-'Analysis Settings'!$F$15),('Raw Data (0-4 Scores)'!J6-'Analysis Settings'!$F$15)/('Analysis Settings'!$F$15-'Analysis Settings'!$E$15))))) -> 0.53673915 | D6: =IF('Raw Data (0-4 Scores)'!K6='Analysis Settings'!$F$16,'Analysis Settings'!$B$9,1/(1+EXP(-'Analysis Settings'!$B$8*IF('Raw Data (0-4 Scores)'!K6>'Analysis Settings'!$F$16,('Raw Data (0-4 Scores)'!K6-'Analysis Settings'!$F$16)/('Analysis Settings'!$G$16-'Analysis Settings'!$F$16),('Raw Data (0-4 Scores)'!K6-'Analysis Settings'!$F$16)/('Analysis Settings'!$F$16-'Analysis Settings'!$E$16))))) -> 0.064197543 | E6: =IF('Raw Data (0-4 Scores)'!L6='Analysis Settings'!$F$17,'Analysis Settings'!$B$9,1/(1+EXP(-'Analysis Settings'!$B$8*IF('Raw Data (0-4 Scores)'!L6>'Analysis Settings'!$F$17,('Raw Data (0-4 Scores)'!L6-'Analysis Settings'!$F$17)/('Analysis Settings'!$G$17-'Analysis Settings'!$F$17),('Raw Data (0-4 Scores)'!L6-'Analysis Settings'!$F$17)/('Analysis Settings'!$F$17-'Analysis Settings'!$E$17))))) -> 0.96632226 | F6: =IF('Raw Data (0-4 Scores)'!M6='Analysis Settings'!$F$18,'Analysis Settings'!$B$9,1/(1+EXP(-'Analysis Settings'!$B$8*IF('Raw Data (0-4 Scores)'!M6>'Analysis Settings'!$F$18,('Raw Data (0-4 Scores)'!M6-'Analysis Settings'!$F$18)/('Analysis Settings'!$G$18-'Analysis Settings'!$F$18),('Raw Data (0-4 Scores)'!M6-'Analysis Settings'!$F$18)/('Analysis Settings'!$F$18-'Analysis Settings'!$E$18))))) -> 0.51471794 | G6: =IF('Raw Data (0-4 Scores)'!N6='Analysis Settings'!$F$19,'Analysis Settings'!$B$9,1/(1+EXP(-'Analysis Settings'!$B$8*IF('Raw Data (0-4 Scores)'!N6>'Analysis Settings'!$F$19,('Raw Data (0-4 Scores)'!N6-'Analysis Settings'!$F$19)/('Analysis Settings'!$G$19-'Analysis Settings'!$F$19),('Raw Data (0-4 Scores)'!N6-'Analysis Settings'!$F$19)/('Analysis Settings'!$F$19-'Analysis Settings'!$E$19))))) -> 0.99723757 | H6: =IF('Raw Data (0-4 Scores)'!O6='Analysis Settings'!$F$20,'Analysis Settings'!$B$9,1/(1+EXP(-'Analysis Settings'!$B$8*IF('Raw Data (0-4 Scores)'!O6>'Analysis Settings'!$F$20,('Raw Data (0-4 Scores)'!O6-'Analysis Settings'!$F$20)/('Analysis Settings'!$G$20-'Analysis Settings'!$F$20),('Raw Data (0-4 Scores)'!O6-'Analysis Settings'!$F$20)/('Analysis Settings'!$F$20-'Analysis Settings'!$E$20))))) -> 0.3913441 | I6: =IF('Raw Data (0-4 Scores)'!P6='Analysis Settings'!$F$21,'Analysis Settings'!$B$9,1/(1+EXP(-'Analysis Settings'!$B$8*IF('Raw Data (0-4 Scores)'!P6>'Analysis Settings'!$F$21,('Raw Data (0-4 Scores)'!P6-'Analysis Settings'!$F$21)/('Analysis Settings'!$G$21-'Analysis Settings'!$F$21),('Raw Data (0-4 Scores)'!P6-'Analysis Settings'!$F$21)/('Analysis Settings'!$F$21-'Analysis Settings'!$E$21))))) -> 0.93754883 | J6: =MIN(I6,1-I6) -> 0.062451171
A7: ='Raw Data (0-4 Scores)'!A7 -> ASE Technology Holding | B7: ='Raw Data (0-4 Scores)'!E7 -> 2025 | C7: =IF('Raw Data (0-4 Scores)'!J7='Analysis Settings'!$F$15,'Analysis Settings'!$B$9,1/(1+EXP(-'Analysis Settings'!$B$8*IF('Raw Data (0-4 Scores)'!J7>'Analysis Settings'!$F$15,('Raw Data (0-4 Scores)'!J7-'Analysis Settings'!$F$15)/('Analysis Settings'!$G$15-'Analysis Settings'!$F$15),('Raw Data (0-4 Scores)'!J7-'Analysis Settings'!$F$15)/('Analysis Settings'!$F$15-'Analysis Settings'!$E$15))))) -> 0.44138201 | D7: =IF('Raw Data (0-4 Scores)'!K7='Analysis Settings'!$F$16,'Analysis Settings'!$B$9,1/(1+EXP(-'Analysis Settings'!$B$8*IF('Raw Data (0-4 Scores)'!K7>'Analysis Settings'!$F$16,('Raw Data (0-4 Scores)'!K7-'Analysis Settings'!$F$16)/('Analysis Settings'!$G$16-'Analysis Settings'!$F$16),('Raw Data (0-4 Scores)'!K7-'Analysis Settings'!$F$16)/('Analysis Settings'!$F$16-'Analysis Settings'!$E$16))))) -> 0.12854498 | E7: =IF('Raw Data (0-4 Scores)'!L7='Analysis Settings'!$F$17,'Analysis Settings'!$B$9,1/(1+EXP(-'Analysis Settings'!$B$8*IF('Raw Data (0-4 Scores)'!L7>'Analysis Settings'!$F$17,('Raw Data (0-4 Scores)'!L7-'Analysis Settings'!$F$17)/('Analysis Settings'!$G$17-'Analysis Settings'!$F$17),('Raw Data (0-4 Scores)'!L7-'Analysis Settings'!$F$17)/('Analysis Settings'!$F$17-'Analysis Settings'!$E$17))))) -> 0.96118792 | F7: =IF('Raw Data (0-4 Scores)'!M7='Analysis Settings'!$F$18,'Analysis Settings'!$B$9,1/(1+EXP(-'Analysis Settings'!$B$8*IF('Raw Data (0-4 Scores)'!M7>'Analysis Settings'!$F$18,('Raw Data (0-4 Scores)'!M7-'Analysis Settings'!$F$18)/('Analysis Settings'!$G$18-'Analysis Settings'!$F$18),('Raw Data (0-4 Scores)'!M7-'Analysis Settings'!$F$18)/('Analysis Settings'!$F$18-'Analysis Settings'!$E$18))))) -> 0.5294104 | G7: =IF('Raw Data (0-4 Scores)'!N7='Analysis Settings'!$F$19,'Analysis Settings'!$B$9,1/(1+EXP(-'Analysis Settings'!$B$8*IF('Raw Data (0-4 Scores)'!N7>'Analysis Settings'!$F$19,('Raw Data (0-4 Scores)'!N7-'Analysis Settings'!$F$19)/('Analysis Settings'!$G$19-'Analysis Settings'!$F$19),('Raw Data (0-4 Scores)'!N7-'Analysis Settings'!$F$19)/('Analysis Settings'!$F$19-'Analysis Settings'!$E$19))))) -> 0.99723757 | H7: =IF('Raw Data (0-4 Scores)'!O7='Analysis Settings'!$F$20,'Analysis Settings'!$B$9,1/(1+EXP(-'Analysis Settings'!$B$8*IF('Raw Data (0-4 Scores)'!O7>'Analysis Settings'!$F$20,('Raw Data (0-4 Scores)'!O7-'Analysis Settings'!$F$20)/('Analysis Settings'!$G$20-'Analysis Settings'!$F$20),('Raw Data (0-4 Scores)'!O7-'Analysis Settings'!$F$20)/('Analysis Settings'!$F$20-'Analysis Settings'!$E$20))))) -> 0.70751215 | I7: =IF('Raw Data (0-4 Scores)'!P7='Analysis Settings'!$F$21,'Analysis Settings'!$B$9,1/(1+EXP(-'Analysis Settings'!$B$8*IF('Raw Data (0-4 Scores)'!P7>'Analysis Settings'!$F$21,('Raw Data (0-4 Scores)'!P7-'Analysis Settings'!$F$21)/('Analysis Settings'!$G$21-'Analysis Settings'!$F$21),('Raw Data (0-4 Scores)'!P7-'Analysis Settings'!$F$21)/('Analysis Settings'!$F$21-'Analysis Settings'!$E$21))))) -> 0.97320073 | J7: =MIN(I7,1-I7) -> 0.026799274
